Workbook

Sheet 环化大会26间酒店名单
A1: 环化大会26间酒店名单(截止11月22日20:00)
A2: 序号 | B2: 酒店名称 | C2: 酒店总房间数/间 | D2: 协议房间数/间 | E2: 已定房间数 | F2: 剩余房间数 | H2: 人数估计
A3: 1 | B3: 江门保利皇冠假日酒店 | C3: 290 | D3: 190 | E3: =贵宾酒店!J5+贵宾酒店!I25+贵宾酒店!J25 -> 159 | F3: 47 | H3: 280
A4: 2 | B4: 江门名冠金凯悦酒店 | C4: 516 | D4: 304 | E4: =贵宾酒店!I44+贵宾酒店!J44+贵宾酒店!J8 -> 248 | F4: =D4-E4 -> 56 | H4: 321
A5: 3 | B5: 江门富力万达嘉华酒店 | C5: 326 | D5: 252 | E5: =贵宾酒店!J6+贵宾酒店!J7+贵宾酒店!I34+贵宾酒店!J34 -> 215 | F5: =D5-E5 -> 37 | H5: 290
A6: 4 | B6: 江门丽宫国际酒店 | C6: 335 | D6: 288 | E6: 280 | F6: 8 | G6: 售罄 | H6: 392
A7: 5 | B7: 江门新会龙泉度假酒店 | C7: 380 | D7: 203 | E7: =贵宾酒店!I58+贵宾酒店!J58 -> 55 | F7: 165 | H7: 228
A8: 6 | B8: 江门新会碧桂园凤凰酒店 | C8: 374 | D8: 202 | E8: =贵宾酒店!I62+贵宾酒店!J62 -> 42 | F8: =D8-E8 -> 160 | H8: 55
A9: 7 | B9: 江门华保体育会展酒店（广东珠西国际会展中心店） | C9: 284 | D9: 100 | E9: =第一批上线!N4+第一批上线!O4 -> 55 | F9: =D9-E9 -> 45 | H9: 102
A10: 8 | B10: 江门银晶国际酒店 | C10: 218 | D10: 184 | E10: =第一批上线!I5+第一批上线!J5+第一批上线!N5+第一批上线!O5 -> 184 | F10: =D10-E10 -> 0 | G10: 售罄 | H10: 187
A11: 9 | B11: 江门蓬江华茵广场亚朵酒店 | C11: 90 | D11: 60 | E11: =第一批上线!I6+第一批上线!I7+第一批上线!N6+第一批上线!N7 -> 60 | F11: =D11-E11 -> 0 | G11: 售罄 | H11: 78
A12: 10 | B12: 铂顿国际公寓江门蓬江行政服务中心店 | C12: 87 | D12: 36 | E12: =第一批上线!I8+第一批上线!N8+第一批上线!N9 -> 36 | F12: =D12-E12 -> 0 | G12: 售罄 | H12: 52
A13: 11 | B13: 维也纳酒店(江门万达广场店) | C13: 60 | D13: 60 | E13: =第一批上线!I10+第一批上线!N10 -> 60 | F13: =D13-E13 -> 0 | G13: 售罄 | H13: 80
A14: 12 | B14: 维也纳酒店(江门常安路步行街店) | C14: 60 | D14: 50 | E14: =第一批上线!I11+第一批上线!N11 -> 49 | F14: =D14-E14 -> 1 | G14: 售罄 | H14: 68
A15: 13 | B15: 江海碧桂园凤凰酒店（江门东站万达广场店） | C15: 193 | D15: 125 | E15: 125 | F15: =D15-E15 -> 0 | G15: 售罄 | H15: 166
A16: 14 | B16: 江门江海智选假日酒店(江海广场店) | C16: 131 | D16: 47 | E16: =第一批上线!I13+第一批上线!N13 -> 47 | F16: =D16-E16 -> 0 | G16: 售罄 | H16: 62
A17: 15 | B17: 江门东站嘉华广场智选假日酒店 | C17: 128 | D17: 75 | E17: =第一批上线!I14+第一批上线!N14 -> 75 | F17: =D17-E17 -> 0 | G17: 售罄 | H17: 65
A18: 16 | B18: 全季酒店（江门东站江海万达广场店） | C18: 113 | D18: 62 | E18: =第一批上线!I15+第一批上线!N15+第一批上线!I16 -> 62 | F18: =D18-E18 -> 0 | G18: 售罄 | H18: 92
A19: 17 | B19: 绿岛假日酒店（江门万达广场华侨广场店） | C19: 166 | D19: 110 | E19: =第二批上线!I5+第二批上线!J5+第二批上线!N5+第二批上线!O5 -> 99 | F19: =D19-E19 -> 11 | G19: 售罄 | H19: 156
A20: 18 | B20: 江门合意酒店 | C20: 88 | D20: 25 | E20: =第二批上线!I6+第二批上线!J6+第二批上线!N6+第二批上线!O6 -> 19 | F20: =D20-E20 -> 6 | G20: 售罄 | H20: 30
A21: 19 | B21: 江门珺璟麦客达温德姆酒店 | C21: 80 | D21: 30 | E21: =第二批上线!I7+第二批上线!N7 -> 30 | F21: =D21-E21 -> 0 | G21: 售罄 | H21: 35
A22: 20 | B22: 希岸Deluxe酒店(江门外海大桥店) | C22: 151 | D22: 100 | E22: =第二批上线!I8+第二批上线!J8+第二批上线!N8+第二批上线!O8 -> 100 | F22: =D22-E22 -> 0 | G22: 售罄 | H22: 150
A23: 21 | B23: 江门奥普斯酒店（江门东站店） | C23: 116 | D23: 70 | E23: =第二批上线!I9+第二批上线!J9+第二批上线!N9+第二批上线!O9 -> 61 | F23: =D23-E23 -> 9 | G23: 售罄 | H23: 97
A24: 22 | B24: 柏丽泉智酒店（江门东站江海广场店） | C24: 70 | D24: 70 | E24: =第二批上线!N14+第二批上线!I14 -> 43 | F24: =D24-E24 -> 27 | H24: 59
A25: 23 | B25: 江门三木里酒店（江海站白水带公园店） | C25: 69 | D25: 46 | E25: =第二批上线!I10+第二批上线!N10+第二批上线!O10 -> 12 | F25: =D25-E25 -> 34 | H25: 16
A26: 24 | B26: 曼陀伦Plus智能酒店(江门和兴广场五邑华侨广场店) | C26: 61 | D26: 38 | E26: =第二批上线!I11+第二批上线!J11+第二批上线!N11+第二批上线!O11 -> 38 | F26: =D26-E26 -> 0 | G26: 售罄 | H26: 38
A27: 25 | B27: 曼陀伦智能酒店(江门职业技术学院店) | C27: 82 | D27: 54 | E27: =第二批上线!I12+第二批上线!J12+第二批上线!N12+第二批上线!O12 -> 23 | F27: =D27-E27 -> 31 | H27: 29
A28: 26 | B28: 丽枫酒店（迎宾大道店） | C28: 136 | D28: 120 | E28: 120 | F28: =D28-E28 -> 0 | G28: 售罄 | H28: 120
A29: 27 | B29: 古镇利和威斯汀酒店 | D29: 40 | E29: 0 | F29: =D29-E29 -> 40 | H29: 0
A30: 28 | B30: 古镇利和希尔顿花园 | D30: 40 | E30: 1 | F30: =D30-E30 -> 39 | H30: 0
A31: 29 | B31: 圭峰大酒店 | D31: 40 | E31: 1 | F31: =D31-E31 -> 39 | H31: 0
A32: 30 | B32: 凯里亚德酒店 | D32: 45 | E32: 1 | F32: =D32-E32 -> 44 | H32: 0
B33: 总计 | D33: =SUM(D3:D28) -> 2901 | E33: =SUM(E3:E28) -> 2297 | F33: =SUM(F3:F28) -> 637 | H33: =SUM(H3:H32) -> 3248

Sheet 贵宾酒店
A4: 序号 | B4: 贵宾类别 | C4: 酒店名称 | D4: 房型 | F4: 数量（间） | I4: 已售((截止11月4日23:59) | J4: 预留(截止11月17日17:00) | K4: 房价（元） | L4: 备注
A5: 1 | B5: VVIP | C5: 江门保利皇冠假日酒店（园山湖店） | D5: 皇冠套房 | F5: 5 | I5: 0 | J5: 0 | K5: 900 | L5: 不上线，VVIP专属套房
A6: 2 | C6: 江门富力万达嘉华酒店 | D6: 豪华套房 | F6: 10 | I6: 0 | J6: 10 | K6: 920
D7: 行政套房 | F7: 2 | I7: 0 | J7: 2 | K7: 920
A8: 3 | C8: 名冠金凯悦酒店 | D8: 豪华套房 | F8: 12 | I8: 0 | J8: 12 | K8: 519
D9: 豪华亲子套房 | F9: 9 | I9: 0 | J9: 9 | K9: 519
D10: 商务套房 | F10: 4 | I10: 0 | J10: 4 | K10: 920
D11: 行政套房 | F11: 5 | I11: 0 | J11: 5 | K11: 920
A12: 4 | C12: 江门丽宫国际酒店 | D12: A座套房 | F12: 8 | K12: 680
C13: 总合计 | F13: =SUM(F5:F12) -> 55 | I13: =SUM(I5:I12) -> 0 | J13: =SUM(J5:J12) -> 42
R14: 线上剩余房间数
F15: 全部总房间数 | G15: 现在线上总房间数 （不含预留不上线房间数） | H15: 减去预留房间数 | I15: 线上已售房间数 | J15: 预留房间数 | T15: 组委免住宿预留表格 | U15: 团房扫码预留表格 | V15: 外籍专家预留表格
I16: 已售（截止11月21日18:00） | J16: (截止11月19日20：00)
A17: 1 | B17: VIP | C17: 江门保利皇冠假日酒店（园山湖店） | D17: 高级大床房（单早） | F17: 20 | G17: 20 | I17: 16 | K17: 450 | L17: 10月8日上线 105间 | M17: =F17-I17-J17 -> 4 | R17: =G17-I17 -> 4
D18: 高级双床房（双早） | F18: 35 | G18: 27 | I18: 27 | J18: 8 | K18: 510 | M18: =F18-I18-J18 -> 0 | R18: =G18-I18 -> 0
D19: 高级城景大床房（单早） | F19: 20 | G19: 12 | H19: =20-J19 -> 12 | I19: 12 | J19: 8 | K19: 500 | M19: =F19-I19-J19 -> 0 | N19: 郑焰房间在预留1间房间数中 | R19: =G19-I19 -> 0 | T19: 9
D20: 高级湖景双床房（双早） | F20: 30 | G20: 30 | H20: =30-J20 -> 30 | I20: 30 | K20: 610 | M20: =F20-I20-J20 -> 0 | R20: =G20-I20 -> 0
D21: 行政双床房 | F21: 10 | G21: 10 | H21: =10-J21 -> 10 | I21: 5 | K21: 758 | M21: =F21-I21-J21 -> 5 | R21: =G21-I21 -> 5
D22: 高级城景双床房（双早） | F22: 20 | G22: 20 | H22: =20-J22 -> 18 | I22: 12 | J22: 2 | K22: 560 | M22: =F22-I22-J22 -> 6 | R22: =G22-I22 -> 8
D23: 行政大床房 | F23: 20 | G23: 12 | H23: =20-J23 -> 17 | I23: 9 | J23: 3 | K23: 758 | M23: =F23-I23-J23 -> 8
D24: 高级湖景大床房（单早） | F24: 30 | G24: 26 | H24: =30-J24 -> 26 | I24: 23 | J24: 4 | K24: 550 | M24: =F24-I24-J24 -> 3 | T24: 3
D25: 合计 | F25: =SUM(F17:F24) -> 185 | I25: =SUM(I17:I24) -> 134 | J25: =SUM(J17:J24) -> 25 | M25: =SUM(M17:M24) -> 26
F26: =F17+F19+F23+F24 -> 90 | G26: =F25-F26 -> 95 | H26: =F26+G26*2 -> 280
A27: 2 | C27: 江门富力万达嘉华酒店 | D27: 豪华大床房（单早） | E27: 60 | F27: 60 | G27: 49 | I27: 48 | J27: 12 | K27: 470 | L27: 10月8日上线 138间 | M27: =F27-I27-J27 -> 0 | N27: 42+8（线下预留）=50 | Q27: 已扣减平台预定赵美训、万莹、张山青5间房间 | R27: =G27-I27 -> 1 | T27: 7 | V27: 4
D28: 豪华双床房（双早） | E28: 43 | F28: 43 | G28: 43 | I28: 41 | J28: 2 | K28: 470 | M28: =F28-I28-J28 -> 0 | N28: 49+1（线下预留）=50 | R28: =G28-I28 -> 2
D29: 高级双床房（双早） | E29: 20 | F29: 20 | G29: 19+1 | I29: 19 | J29: 0 | K29: 470 | M29: =F29-I29-J29 -> 1 | R29: =G29-I29 -> #VALUE!
D30: 行政大床房（单早） | E30: 33 | F30: 28 | G30: 28 | I30: 27 | K30: 470 | M30: =F30-I30-J30 -> 1 | R30: =G30-I30 -> 1
D31: 行政大床房（单早） | E31: 12 | F31: 17 | G31: 17 | H31: =17-J31 -> 2 | I31: 0 | J31: 15 | K31: 470 | L31: 预留72间 | M31: =F31-I31-J31 -> 2 | R31: =F32-I32 -> 12 | T31: 1
D32: 行政双床房（双早） | E32: 12 | F32: 12 | G32: 3 | H32: =12-J32 -> 1 | I32: 0 | J32: 11 | K32: 470 | M32: =F32-I32-J32 -> 1 | R32: =F33-J33 -> 32 | T32: 9
D33: 高级大床房（单早） | E33: 60 | F33: 60 | G33: 31 | H33: =60-J33 -> 32 | I33: 0 | J33: 28 | K33: 470 | M33: =F33-I33-J33 -> 32 | N33: 23（线下预留），为避免后续此房型上线预订时出现超房情况，线上改为27间，总房数23+27=50 | T33: 29
D34: 合计 | F34: =SUM(F27:F33) -> 240 | I34: =SUM(I27:I33) -> 135 | J34: =SUM(J27:J33) -> 68 | M34: =SUM(M27:M33) -> 37
F35: =F27+F30+F31+F33 -> 165 | G35: =F34-F35 -> 75 | H35: =F35+G35*2 -> 315
A36: 3 | C36: 名冠金凯悦酒店 | D36: 高级大床房（单早） | F36: 21 | G36: 21 | I36: 21 | K36: 399 | M36: 0 | R36: =G36-I36 -> 0
D37: 高级双床房（双早） | F37: 42 | G37: 42 | I37: 42 | K37: 399 | M37: 0 | R37: =G37-I37 -> 0
D38: 豪华大床房（单早） | F38: 54 | G38: 44 | H38: =54-J38 -> 25 | I38: 25 | J38: 29 | K38: 438 | L38: 10月8日上线 134间 | M38: =F38-I38-J38 -> 0 | N38: 54-3（线下预留）=51（系统显示总房数） | R38: =G38-I38 -> 19 | T38: 9 | V38: 1
D39: 豪华双床房（双早） | F39: 30 | G39: 26 | I39: 16 | J39: 13 | K39: 438 | M39: =F39-I39-J39 -> 1 | R39: =G39-I39 -> 10
D40: 主题养生单人房（单早） | F40: 44 | G40: 40 | H40: =44-J40 -> 12 | I40: 9 | J40: 32 | K40: 470 | M40: =F40-I40-J40 -> 3 | N40: 44-1（线下预留）=43（系统显示总房数） | R40: =G40-I40 -> 31 | T40: 3 | U40: 1
D41: 臻享商务单人房（单早） | F41: 15 | G41: 13 | H41: =15-J41 -> 9 | I41: 9 | J41: 6 | K41: 470 | M41: =F41-I41-J41 -> 0 | N41: 15-2（线下预留）=13（系统显示总房数） | R41: =G41-I41 -> 4 | T41: 4
D42: 行政单人房（单早） | F42: 17 | G42: 17 | H42: =17-J42 -> 16 | I42: 0 | J42: 1 | K42: 550 | M42: =G42-I42-J42 -> 16
D43: 商务单人房（单早） | F43: 51 | G43: 51 | H43: =51-J43 -> 18 | I43: 0 | J43: 33 | K43: 470 | M43: =G43-I43-J43 -> 18 | T43: 1
...

Sheet 第一批上线
A1: 环化大会第一批可上线酒店
A2: 片区 | B2: 序号 | C2: 酒店名称 | D2: 酒店给房数 | E2: 酒店类型 | F2: 大床房 | K2: 双床房
F3: 房型说明 | G3: 房价（元/晚） | H3: 数量（间） | I3: 已售（截止11月17日15:30） | J3: 预留(截止11月12日23:59) | K3: 房型说明 | L3: 房价（元/晚） | M3: 数量（间） | N3: 已售（截止11月17日15:30） | O3: 预留(截止11.19
B4: 1 | C4: 江门华保体育会展酒店（广东珠西国际会展中心滨江体育中心店） | D4: 60 | E4: 商务 | K4: 双床房（双早） | L4: —— | M4: 100 | N4: 55
B5: 2 | C5: 江门银晶国际酒店 | D5: =H5+M5 -> 184 | E5: 商务 | F5: 大床房（含双早） | G5: 200 | H5: 69 | I5: 69 | J5: 0 | K5: 双床房（含双早） | L5: —— | M5: 115 | N5: 69 | O5: 46 | P5: 售罄
B6: 3 | C6: 江门蓬江华茵广场亚朵酒店 | D6: =H6+H7+M6+M7 -> 60 | E6: 商务 | F6: 行政大床房（双早） | G6: 450 | H6: 20 | I6: 20 | K6: 行政双床房（双早） | L6: —— | M6: 10 | N6: 10 | P6: 售罄
F7: 几木大床房（双早） | G7: 500 | H7: 20 | I7: 20 | K7: 几木双床房（双早） | L7: 450 | M7: 10 | N7: 10 | P7: 售罄
B8: 4 | C8: 铂顿国际公寓江门蓬江行政服务中心店 | D8: =H8+H9+M8+M9 -> 36 | E8: 商务 | F8: 豪华城景大床-含早 | G8: 356 | H8: 20 | I8: 20 | K8: 豪华城景双床-含早 | L8: 500 | M8: 8 | N8: 8 | P8: 售罄
K9: 轻奢城景双床-含早 | L9: 311 | M9: 8 | N9: 8 | P9: 售罄
B10: 5 | C10: 维也纳酒店(江门万达广场店) | D10: =H10+M10 -> 60 | E10: 商务 | F10: 大床房-含早 | G10: 318 | H10: 40 | I10: 40 | K10: 双床房-含早 | L10: 359 | M10: 20 | N10: 20 | P10: 售罄
B11: 6 | C11: 维也纳酒店(江门常安路步行街店) | D11: =H11+M11 -> 50 | E11: 舒适型 | F11: 豪华大床-含早 | G11: 200 | H11: 30 | I11: 30 | K11: 豪华双床-含早 | L11: 338 | M11: 20 | N11: 19 | O11: 1 | P11: 售罄
A12: 江海区 | B12: 7 | C12: 江海碧桂园凤凰酒店（江门东站万达广场店） | D12: =H12+M12 -> 125 | E12: 商务 | F12: 大床房（单早） | G12: 260 | H12: 54 | I12: 44 | J12: 10 | K12: 双床房（双早） | L12: 200 | M12: 71 | N12: 61 | O12: 10 | P12: =H12-I12-J12-N12-O12+M12 -> 0 | Q12: 售罄
B13: 8 | C13: 江门江海智选假日酒店(江海广场店) | D13: =H13+M13 -> 47 | E13: 商务 | F13: 大床房（单早） | G13: 299 | H13: 32 | I13: 32 | K13: 双床房（双早） | L13: 260 | M13: 15 | N13: 15 | P13: 售罄
B14: 9 | C14: 江门东站嘉华广场智选假日酒店 | D14: =H14+M14 -> 75 | E14: 商务 | F14: 大床房（单早） | G14: 289 | H14: 40 | I14: 40 | K14: 双床房（双早） | L14: 299 | M14: 35 | N14: 35 | P14: 售罄
B15: 10 | C15: 全季酒店（江门东站江海万达广场店） | D15: =H15+M15+H16 -> 62 | E15: 商务 | F15: 大床房（单早） | G15: 300 | H15: 30 | I15: 30 | K15: 双床房（双早） | L15: 289 | M15: 30 | N15: 30 | P15: 售罄
F16: 套房（含早） | G16: 480 | H16: 2 | I16: 2 | K16: —— | L16: 300 | P16: 售罄
A17: 合计 | D17: =H17+M17 -> 799 | E17: - | H17: =SUM(H4:H16) -> 357 | I17: =SUM(I4:I16) -> 347 | J17: =SUM(J4:J16) -> 10 | L17: —— | M17: =SUM(M4:M16) -> 442 | N17: =SUM(N4:N15) -> 340 | O17: =SUM(O4:O16) -> 57
D20: 已订 | E20: =I17+N17+J17+O17 -> 754 | H20: 余房 | I20: =H17+M17-I17-J17-N17-O17 -> 45
D21: 余房 | E21: =D17-I17-N17-J17-O17 -> 45

Sheet 第二批上线
A1: 环化大会拟第二批上线酒店
A2: 序号 | B2: 酒店名称 | C2: 酒店总房数 | D2: 给房数 | E2: 酒店类型 | F2: 大床房 | K2: 双床房
F3: 房型说明 | G3: 房价（元/晚） | H3: 数量（间） | I3: 已售(截止11月14日15:30) | J3: 预留（截止11月17日15:30） | K3: 房型说明 | L3: 房价（元/晚） | M3: 数量（间） | N3: 已售（截止11月17日15:30） | O3: 预留(截止11月19日18:50)
A4: 1 | B4: 江门丽宫国际酒店B座 | C4: 335 | D4: =H4+M4 -> 144 | E4: 豪华 | F4: B座陈韵雅致大床（双早） | G4: 248 | H4: 96 | I4: 77 | J4: 12 | K4: B座陈韵雅致双床（双早） | L4: 248 | M4: 48 | N4: 48 | P4: =H4-I4-J4+M4-N4 -> 7 | Q4: 售罄
A5: 3 | B5: 绿岛假日酒店（江门万达广场华侨广场店） | C5: 166 | D5: =H5+M5 -> 119 | E5: 商务 | F5: ——（含双早） | G5: 200 | H5: 39 | I5: 34 | J5: 5 | K5: ——（含双早） | L5: 200 | M5: 80 | N5: 51 | O5: 9 | P5: 售罄
A6: 4 | B6: 江门合意酒店 | D6: =H6+M6 -> 35 | E6: 商务 | F6: ——（含双早） | G6: 238 | H6: 20 | I6: 15 | K6: ——（含双早） | L6: 238 | M6: 15 | N6: 4 | P6: 售罄
A7: 5 | B7: 江门珺璟麦客达温德姆酒店 | C7: 80 | D7: =H7+M7 -> 30 | E7: 准四 | F7: 大床房（单早） | G7: 300 | H7: 25 | I7: 25 | K7: 双床房（双早） | L7: 360 | M7: 5 | N7: 5 | P7: 售罄
A8: 6 | B8: 希岸Deluxe酒店(江门外海大桥店) | C8: 151 | D8: =H8+M8 -> 100 | E8: 商务 | F8: 江景大床房（单早） | G8: 360 | H8: 50 | I8: 50 | K8: 商务双床房（双早） | L8: 360 | M8: 50 | N8: 50 | P8: 售罄
A9: 7 | B9: 江门奥普斯酒店（江门东站店） | C9: 116 | D9: =H9+M9 -> 70 | E9: 商务 | F9: 大床房（单早） | G9: 240 | H9: 40 | I9: 37 | J9: 2 | K9: 双床房（双早） | L9: 260 | M9: 30 | N9: 22 | P9: 售罄
A10: 11 | B10: 江门三木里酒店（江海站白水带公园店） | C10: 69 | D10: =H10+M10 -> 46 | E10: 商务 | F10: 大床房（单早） | G10: 258 | H10: 28 | I10: 8 | K10: 双床房（双早） | L10: 280 | M10: 18 | N10: 4
A11: 12 | B11: 曼陀伦Plus智能酒店(江门和兴广场五邑华侨广场店) | C11: 61 | D11: =H11+M11 -> 38 | E11: 商务 | F11: 大床房（单早） | G11: 270 | H11: 33 | I11: 33 | K11: 双床房（双早） | L11: 280 | M11: 5 | N11: 5 | P11: 售罄
A12: 13 | B12: 曼陀伦智能酒店(江门职业技术学院店) | C12: 82 | D12: =H12+M12 -> 54 | E12: 商务 | F12: 大床房（单早） | G12: 200 | H12: 36 | I12: 15 | K12: 双床房（双早） | L12: 200 | M12: 18 | N12: 8
B13: 丽枫酒店（迎宾大道店） | D13: 120 | F13: 大床房（单早） | G13: 250 | H13: 70 | I13: 45 | J13: 24 | K13: 双床房（双早） | L13: 270 | M13: 50 | N13: 0 | O13: 50 | P13: 1
B14: 柏丽泉智酒店（江门东站江海广场店） | D14: 70 | F14: 大床房（单早） | G14: 258 | H14: 50 | I14: 25 | J14: 1 | K14: 双床房（双早） | L14: 258 | M14: 20 | N14: 18
E15: - | F15: =H15+M15 -> 826 | H15: =SUM(H4:H14) -> 487 | I15: =SUM(I4:I14) -> 364 | J15: =SUM(J4:J14) -> 44 | M15: =SUM(M4:M14) -> 339 | N15: =SUM(N4:N14) -> 215 | O15: =SUM(O4:O14) -> 59
G18: 余房 | H18: =F15-I15-J15-N15-O15 -> 144

Sheet 组委会预留名单
A1: 组委会预留名单
A2: 姓名 | B2: 院校 | C2: 入住酒店 | D2: 房型 | E2: 入住日期 | F2: 退房日期 | G2: 入住天数 | H2: 房间数量（间） | I2: 酒店单价（元） | J2: 应收房费（元） | K2: 备注 | L2: 信息来源
A3: 许继文 | B3: 南科大 资助81人,41间房 | C3: 江门银晶国际酒店 | D3: 双床房（含双早） | E3: 45989 | F3: 45991 | G3: =F3-E3 -> 2 | H3: 1 | I3: 200 | J3: =I3*H3*G3 -> 400
A4: 10人 | E4: 45989 | F4: 45992 | G4: 3 | H4: 5 | I4: 200 | J4: =G4*H4*I4 -> 3000
A5: 69人 | E5: 45989 | F5: 45993 | G5: 4 | H5: 35 | I5: 200 | J5: =G5*H5*I5 -> 28000 | K5: 免住宿 | L5: 刘长宇
A6: 江桂斌（院士） | B6: 中国科学院生态环境研究中心 | C6: 江门富力万达嘉华酒店 | D6: 行政套房 | E6: 45989 | F6: 45993 | G6: 4 | H6: 1 | I6: 920 | J6: 3680 | K6: 线下付款，不能催付款 | L6: 刘长宇
A7: 李景虹（院士） | B7: 清华大学 | C7: 江门富力万达嘉华酒店 | D7: 豪华套房 | E7: 45989 | F7: 45991 | G7: 2 | H7: 1 | I7: 920 | J7: 1840 | K7: 免住宿 | L7: 刘长宇
A8: 薛其坤（院士） | B8: 中国科学院院士 | C8: 江门富力万达嘉华酒店 | D8: 行政套房 | E8: 45989 | F8: 45991 | G8: 2 | H8: 1 | I8: 920 | J8: =G8*H8*I8 -> 1840 | K8: 免住宿，万达最好套房，近江院士房间 | L8: 刘长宇 | M8: 已与万达经理沟通，安排的两个行政套房在同一层，间隔10米
A9: Susan D. Richardson | B9: University of South Carolina | C9: 江门富力万达嘉华酒店 | D9: 豪华套房 | E9: 45990 | F9: 45993 | G9: 3 | H9: 1 | I9: 470 | J9: 1410 | K9: 免住宿 | L9: 刘长宇
A10: Fabio Pulizzi | C10: 江门富力万达嘉华酒店 | D10: 豪华套房 | E10: 45992 | F10: 45994 | G10: 2 | H10: 1 | I10: 920 | J10: =G10*H10*I10 -> 1840 | K10: 免住宿 | L10: 刘长宇29
A11: 万莹 | B11: 基金委 | C11: 江门富力万达嘉华酒店 | D11: 豪华大床房 | E11: 45989 | F11: 45992 | G11: =F11-E11 -> 3 | H11: 0 | I11: 470 | J11: 1880 | K11: 免住宿，预订平台已登记1间 | L11: 刘长宇
A12: 庄乾坤 | C12: 江门富力万达嘉华酒店 | D12: 豪华大床房 | E12: 45991 | G12: 4 | H12: 1 | I12: 470 | J12: 1880 | K12: 免住宿 | L12: 刘长宇
A13: 王春霞 | C13: 江门富力万达嘉华酒店 | D13: 豪华大床房 | E13: 待定 | G13: 4 | H13: 1 | I13: 470 | J13: 1880 | K13: 免住宿 | L13: 刘长宇
A14: 余立风 | C14: 江门富力万达嘉华酒店 | D14: 豪华大床房 | E14: 待定 | H14: 1 | I14: 470 | K14: 免住宿
A17: 张金龙（院士） | B17: 华东理工大学 | C17: 名冠金凯悦酒店 | D17: 豪华套房 | E17: 45989 | F17: 45992 | G17: 3 | H17: 1 | I17: 519 | J17: =G17*H17*I17 -> 1557 | K17: 免住宿 | L17: 刘长宇
A18: 朱利中（院士） | B18: 浙江大学 | C18: 江门富力万达嘉华酒店 | D18: 豪华套房 | E18: 45989 | F18: 45992 | G18: 3 | H18: 1 | I18: 920 | J18: 2760 | K18: 免住宿，预订平台已登记
A19: 陈春城 | B19: 中国科学院化学研究所 | C19: 名冠金凯悦酒店 | D19: 商务单人房 | E19: 45989 | F19: 45992 | G19: =F19-E19 -> 3 | H19: 1 | I19: 470 | J19: =G19*H19*I19 -> 1410 | K19: 专家自付
A20: 张涛院士 | B20: 张涛院士 | C20: 江门富力万达嘉华酒店 | D20: 豪华套房 | E20: 45989 | H20: 1 | I20: 920 | K20: 大会免住宿 | L20: 2张餐票，最好的套房 （带家属）
B21: 院士随行人员 | C21: 江门富力万达嘉华酒店 | D21: 高级大床房 | E21: 45989 | H21: 1 | I21: 470
A22: 刘维屏 | B22: 专委会委员 | C22: 江门富力万达嘉华酒店 | D22: 高级大床房 | E22: 45989 | F22: 45992 | G22: =F22-E22 -> 3 | H22: 1 | I22: 470 | J22: =G22*H22*I22 -> 1410 | K22: 专家自付
A23: 阚海东 | C23: 江门富力万达嘉华酒店 | D23: 高级大床房 | E23: 45989 | F23: 45991 | G23: =F23-E23 -> 2 | H23: 1 | I23: 470 | J23: =G23*H23*I23 -> 940
A24: 要茂盛 | C24: 江门富力万达嘉华酒店 | D24: 高级大床房 | E24: 45988 | H24: 1 | I24: 470
A25: 冯新斌 | C25: 江门富力万达嘉华酒店 | D25: 高级大床房 | E25: 45989 | F25: 45992 | G25: =F25-E25 -> 3 | H25: 1 | I25: 470 | J25: =G25*H25*I25 -> 1410
A26: 王秋泉 | C26: 江门富力万达嘉华酒店 | D26: 高级大床房 | E26: 45988 | F26: 45991 | G26: =F26-E26 -> 3 | H26: 1 | I26: 470 | J26: =G26*H26*I26 -> 1410
A27: 吴永宁 | C27: 江门富力万达嘉华酒店 | D27: 高级大床房 | E27: 45989 | F27: 45992 | G27: =F27-E27 -> 3 | H27: 1 | I27: 470 | J27: =G27*H27*I27 -> 1410
A28: 孙红文 | C28: 江门富力万达嘉华酒店 | D28: 高级大床房 | E28: 45989 | F28: 45992 | G28: =F28-E28 -> 3 | H28: 1 | I28: 470 | J28: =G28*H28*I28 -> 1410
A29: 吴永宁 | C29: 江门富力万达嘉华酒店 | D29: 高级大床房 | E29: 45989 | F29: 45991 | G29: =F29-E29 -> 2 | H29: 1 | I29: 470 | J29: =G29*H29*I29 -> 940
A30: 宋茂勇 | C30: 江门富力万达嘉华酒店 | D30: 高级大床房 | E30: 45989 | F30: 45992 | G30: =F30-E30 -> 3 | H30: 1 | I30: 470 | J30: =G30*H30*I30 -> 1410
H31: =SUM(H3:H28) -> 61
A32: 俞汉青（院士） | B32: 中国科学技术大学 | C32: 江门富力万达嘉华酒店 | D32: 行政大床房 | E32: 45989 | F32: 45993 | G32: 4 | H32: 1 | I32: 470 | J32: 1880 | K32: 免住宿 | L32: 刘长宇
A33: 陶澍 | B33: 北京大学 | C33: 名冠金凯悦酒店 | D33: 行政套房 | H33: 1
A34: 付贤智 | B34: 福州大学 | C34: 名冠金凯悦酒店 | D34: 行政套房 | E34: 45989 | F34: 45990 | G34: =F34-E34 -> 1 | H34: 1 | I34: 920 | J34: =I34*H34*G34 -> 920
B35: 付贤智院士陪同人员 | C35: 名冠金凯悦酒店 | D35: 商务单人房 | E35: 45989 | F35: 45990 | G35: =F35-E35 -> 1 | H35: 1 | I35: 470 | J35: =I35*H35*G35 -> 470
A36: 柴之芳（夫妇） | B36: 中国科学院高能物理研究所 | C36: 名冠金凯悦酒店 | D36: 行政套房 | H36: 1 | L36: 两张餐票，要最好的套房（带家属）
A37: 沈洪兵 | B37: 国家卫生健康委员会 | C37: 江门富力万达嘉华酒店 | D37: 豪华套房 | E37: 45990 | F37: 45991 | H37: 1 | I37: 920 | L37: 要最好的套房
A38: 郝吉明 | B38: 清华大学 | C38: 名冠金凯悦酒店 | D38: 行政套房 | H38: 1
A39: 汪华林 | B39: 华东理工大学 | C39: 名冠金凯悦酒店 | D39: 商务套房 | H39: 1
A40: 杨志峰 | B40: 广东工业大学 | C40: 名冠金凯悦酒店 | D40: 商务套房 | H40: 1
A41: 贺泓 | B41: 中国科学院生态环境研究中心 | C41: 名冠金凯悦酒店 | D41: 豪华套房 | H41: 1
A42: 吴丰昌 | B42: 中国环境科学研究院 | C42: 名冠金凯悦酒店 | D42: 豪华套房 | H42: 1
...

Sheet 外籍专家预留
A1: 第十三届全国环境化学大会外籍专家用房登记（收集结果）
A3: 序号 | B3: 提交者 | C3: 联系人 | D3: 联系方式 | E3: 证件名称 | F3: 证件号码 | G3: 入住酒店 | H3: 房型 | I3: 入住日期 | J3: 退房日期 | K3: 入住天数 | L3: 房间数量（间） | M3: 酒店单价（元） | N3: 应收房费（元） | O3: 备注 | P3: 收费形式
A4: 1 | B4: 刘素琴 | C4: 刘素琴 | D4: 13466371647 | E4: HG627404 | F4: X. Chris Le | G4: 江门富力万达嘉华酒店 | H4: 豪华大床房 | I4: 45989 | J4: 45993 | K4: 4 | L4: 1 | M4: 470 | N4: 1880 | O4: Xing-Fang Li 同住 | P4: POS机支付
A5: 2 | B5: Xiangru 张相如 | C5: 张相如 | D5: 14714315819 | E5: 张相如 | F5: H60155102 | G5: 江门富力万达嘉华酒店 | H5: 豪华大床房 | I5: 45989 | J5: 45993 | K5: 4 | L5: 1 | M5: 470 | N5: 1880 | P5: POS机支付
A6: 3 | B6: RN | C6: Raman Novikau | D6: 17868746908 | E6: Passport | F6: AB3489892 | G6: 江门银晶国际酒店 | H6: 大床房 | I6: 45988 | J6: 45994 | K6: 6 | L6: 1 | M6: 200 | N6: 1200 | P6: 微信/支付宝扫码支付
A7: 4 | B7: Qihong Lu | C7: 鲁祺鸿 | D7: 13430392474 | E7: He jianzhong | F7: K2071792E | G7: 江门富力万达嘉华酒店 | H7: 豪华双床房（无房，改行政双床） | I7: 45989 | J7: 45992 | K7: 3 | L7: 1 | M7: 470 | N7: 1410 | O7: 带小朋友最好有儿童房 | P7: 微信/支付宝扫码支付
A8: 5 | B8: 周蕾 | C8: 周蕾 | D8: 15010132107 | E8: Lucia Muñoz Franco | F8: NP9H53J18 | G8: 江门富力万达嘉华酒店 | H8: 豪华大床房 | I8: 45989 | J8: 45993 | K8: 4 | L8: 2 | M8: 470 | N8: 3760 | P8: POS机支付
A9: 6 | B9: 孔多多 | C9: 于志刚 | D9: 18569509240 | E9: 于志刚 | F9: EQ6317073 | G9: 名冠金凯悦酒店 | H9: 豪华大床房 | I9: 45989 | J9: 45994 | K9: 5 | L9: 1 | M9: 438 | N9: 2190 | P9: POS机支付
A10: 7 | B10: Paul | C10: 王坡 | D10: 18565359691 | E10: Charles Shiu Wong | F10: 56662970 | G10: 名冠金凯悦酒店 | H10: 豪华大床房 | I10: 45989 | J10: 45993 | K10: 4 | L10: 1 | M10: 438 | N10: 1752
A11: 8 | B11: 孔多多 | C11: 孔德懿 | D11: 17768103485 | E11: Jianhua Guo | F11: EB4922180 | G11: 名冠金凯悦酒店 | H11: 豪华大床房 | I11: 45989 | J11: 45993 | K11: 4 | L11: 1 | M11: 438 | N11: 1752 | O11: 召集人 | P11: POS机支付
A12: 9 | B12: 西小瓜 | C12: 杨晓溪 | D12: 18810982539 | E12: JEONGEUN OH | F12: M95504585 | G12: 江门富力万达嘉华酒店 | H12: 豪华大床房 | I12: 45989 | J12: 45992 | K12: 3 | L12: 1 | M12: 470 | N12: 1410 | O12: 联系人支付房费 | P12: 微信/支付宝扫码支付
A13: 10 | B13: 想五天 | C13: 伍天翔 | D13: 18342207307 | E13: Daniel Keith Schlenk | F13: A03580668 | G13: 名冠金凯悦酒店 | H13: 臻享商务单人房（75寸彩电）（单早） | I13: 45989 | J13: 45994 | K13: 5 | L13: 1 | M13: 470 | N13: 2350
A14: 11 | B14: 姜晓刚 ACS | C14: 姜晓刚 | D14: 13051706665 | E14: Margaret Mills | F14: 547817624 | G14: 江门富力万达嘉华酒店 | H14: 豪华双床房（无房，改行政双床） | I14: 45989 | J14: 45993 | K14: 4 | L14: 1 | M14: 470 | N14: 1880 | P14: POS机支付
A15: 12 | B15: Qihong Lu | C15: 鲁祺鸿 | D15: 13430392474 | E15: Bayeshova Saltant | F15: N16193992 | G15: 江门富力万达嘉华酒店 | H15: 豪华双床房（无房，改行政双床） | I15: 45989 | J15: 45992 | K15: 3 | L15: 1 | M15: 470 | N15: 1410 | O15: 与Nurzhanova Assil 同住 | P15: 微信/支付宝扫码自付
A16: 13 | B16: LB | C16: 梁斌 | D16: 13910740863 | E16: Hnkolaeb/Nikolave | F16: 758939538 | G16: 江门富力万达嘉华酒店 | H16: 豪华双床房（无房，改行政双床） | I16: 45989 | J16: 45992 | K16: 3 | L16: 2 | M16: 470 | N16: 2820 | O16: 大床+双床各一个，填的房间数3间，按高级大床1间+豪华双床2间 | P16: POS机支付
H17: 高级大床房 | I17: 45989 | J17: 45992 | K17: 3 | L17: 1 | M17: 470 | N17: 1410
A18: 14 | B18: Paul | C18: 王坡 | D18: 18565359691 | E18: Derek Charles Gordon Muir | F18: HM321274 | G18: 名冠金凯悦酒店 | H18: 豪华大床房 | I18: 45989 | J18: 45993 | K18: 4 | L18: 1 | M18: 438 | N18: 1752 | O18: 加拿大皇家科学院院士免住宿费（五邑大学初步计划由组委会付房费） | P18: 微信/支付宝扫码自付
A19: 15 | B19: 李萌 | C19: 李萌 | D19: 18810153826 | E19: Grace Evelyn Thoburn | F19: 131183487 | G19: 名冠金凯悦酒店 | H19: 豪华大床房 | I19: 45988 | J19: 45994 | K19: 6 | L19: 1 | M19: 438 | N19: 2628 | P19: 微信/支付宝扫码自付
A20: 16 | B20: 姜晓刚 ACS | C20: 姜晓刚 | D20: 13051706665 | E20: Wonyong Choi | F20: M477K8635 | G20: 江门富力万达嘉华酒店 | H20: 豪华大床房 | I20: 45989 | J20: 45993 | K20: 4 | L20: 1 | M20: 470 | N20: 1880 | O20: 美国外籍院士 | P20: POS机支付
A21: 17 | B21: 李萌 | C21: 李萌 | D21: 18810153826 | E21: Peter Vikesland | F21: A80684012 | G21: 名冠金凯悦酒店 | H21: 豪华大床房 | I21: 45991 | J21: 45994 | K21: 3 | L21: 1 | M21: 438 | N21: 1314
C22: 萧锦荣 | D22: 13853128391 | E22: SIU, KAM WING MICHAEL | F22: H04254584 | G22: 江门富力万达嘉华酒店 | H22: 豪华大床房 | I22: 45989 | J22: 45992 | K22: 3 | L22: 1 | M22: 470 | N22: 1410 | P22: 微信/支付宝扫码自付
C23: 姜晓刚 | D23: 13051706665 | E23: Trevor David Waite | F23: RA2015710 | G23: 江门富力万达嘉华酒店 | H23: 豪华大床房 | I23: 45989 | J23: 45993 | K23: 4 | L23: 1 | M23: 470 | N23: 1880 | O23: 美国外籍院士，大会付费（备注大会付费，由组委会付房费？） | P23: POS机支付
C24: 孔德懿 | D24: 17768103485 | E24: Mengyan Li | F24: EK0010988 | G24: 江门名冠金凯悦酒店 | H24: 豪华大床房 | I24: 45989 | J24: 45993 | K24: 4 | L24: 1 | M24: 438 | N24: 1752 | P24: POS机支付

Sheet 特殊事项备注
A1: 订单号/注册号 | B1: 姓名 | C1: 电话 | D1: 预订酒店 | E1: 房型 | F1: 入住时间 | G1: 备注 | H1: 备注
A2: 20695273 | B2: 邹依霖 | C2: 13039330050 | D2: 江门丽宫国际酒店 | E2: A座高级双床房 | G2: 需要再加一张床
A3: 4138 | B3: 侯德义 | C3: 18548911918 | D3: 江门富力万达嘉华酒店（VIP预留） | E3: 豪华大床房 | G3: 需要酒店开票
A4: 778 | B4: 申芳霞 | C4: 15210592958 | D4: 江门富力万达嘉华酒店 | E4: 豪华大床房(单 | G4: 将入住时间从“11.27-12.1日”改为“11.28-12.2日” | H4: 已修改
A5: 4734 | B5: 乔琰 | C5: 15210592958 | D5: 江海智选假日酒店 | E5: 大床房 | G5: 将入住时间从“11.28-12.2日”改为“11.28-12.1日” | H5: 重复
A6: 2616 | B6: 陈洁 | C6: 15373575957 | D6: 间维也纳酒店(江门常安路步行街店) | E6: 豪华双床房 | G6: 将入住时间从“11.28-12.1日”改为“11.28-12.2日” | H6: 重复
B7: 周婧 | C7: 18099242227 | D7: 江门新会碧桂园凤悦凤凰酒店 | E7: 2间大床+1间双床 | F7: 11.28日-12-2日 | G7: 预留，自行线下支付
B8: 谢静 | C8: 北京理工大学 | D8: 江门蓬江华茵广场亚朵酒店 | G8: 将入住时间从“11.28-12.2日”改为“11.28-12.1日” | H8: 重复
B9: 王丁一 | C9: 中科院生态环境研究中心 | D9: 江门富力万达嘉华酒店 | E9: 豪华双床房 | F9: 11.28日-12-2日 | G9: 将入住时间从“11.28-12.2日”改为“11.28-12.1日” | H9: 重复
A10: 4152 | B10: 郑明辉 | C10: 13621093063 | D10: 江门富力万达嘉华酒店（VIP预留） | E10: 行政大床房（单早）/整间/CNY470.00/天 | G10: 万达套房，11.28—2日
B11: 姜璐 | D11: 江门富力万达嘉华酒店（VIP预留） | E11: 高级双床房（双早）（整间） | F11: 2025-11-27 2025-12-02 | G11: 跟陈伟芳合住，金额对半，发票分开开，一半为内蒙古大学的发票信息（纳税人识别号：1215000046002920XK）具体见下方，一半为中国科学院生态环境研究中心（纳税人识别号：121000004000122540） 名称：内蒙古大学 纳税人识别号：1215000046002920XK 单位地址：呼和浩特市赛罕区大学西路235号 电话号码：0471-4994142 开户行：中国建设银行股份有限公司呼和浩特赛罕区支行 联行号：105191075085 银行账号：15001706667050001905
B12: 张建清 | G12: 尊敬的会务组老师， 你好！因单位财务报账要求，我科室2名参会人员需提前开具注册费和酒店住宿费发票，申请人信息如下： 单位：深圳市疾病预防控制中心，申请人1姓名：张建清，手机号：13501580586，邮箱：969676617@qq.com； 申请人2：彭金铃，13688815730，邮箱：453448942@qq.com。谢谢！ | H12: 已修改
G13: 我预定了环化大会期间维也纳酒店(江门常安路步行街店) 豪华双床房（双早） 2间3晚（11月28日入住-12月1日离店）。现因行程变动，2间房均需延长一晚至12月2日离店，请帮忙处理，谢谢！ 联系方式：陈女士（电话：15373575957） | H13: 已处理
G14: 您好，我预定了江门丽宫国际酒店（VIP预留） A座高级大床房（单早） （整间） （2*6晚） 我在网站上申请了退款，但担心退款成功后没有房间了，所以发邮件问一下是否能帮忙直接修改，保留我的订单，将入住日期修改成11月28日，退房日期为12月2日，房间数量修改为1间。谢谢！ 史亚利 中国科学院生态环境研究中心 环境化学与生态毒理学国家重点实验室 离子色谱和新型污染物分析研究组 e-mail:shiyali@rcees.ac.cn | H14: 已处理
G15: 您好，我的订单房间日期选错了，应为11.28入住，12.2日退房。麻烦帮忙进行变更 订单信息见附件。 谢谢。 祝好 芳霞 =============================== 申芳霞 博士 卓越百人副教授 能源与动力工程学院 北京航空航天大学 Mobile: (+86) 15210592958 Email: fxshen@buaa.edu.cn | H15: 已处理
G16: =_xlfn.DISPIMG("ID_06507F065DEA4E858E4DC8F8E87C7C63",1) -> =DISPIMG("ID_06507F065DEA4E858E4DC8F8E87C7C63",1) | H16: 具体信息：杨超 豪华大床房 我原预定的酒店江门富力万达嘉华酒店11月28至12月1日 3晚，请更改至11月29日至11月30日 1晚。 | I16: 不改了，已处理
G17: 大会组委会，您好！ 我是中国科学院生态环境研究中心刘稷燕，为参加环化大会，我已经预定住宿并已经缴纳了费用（1500元），缴费记录请见附件。依据目前安排好的行程，我的住宿希望变更为11月28日入住，12月2日离店，住宿4晚，麻烦您帮忙作住宿时间变更，谢谢！ 刘稷燕 | H17: 已修改等付费
G18: 会务组您好： 麻烦将我预定的丽宫酒店20251128-20251202的酒店改成11月30号到-12月2号离店两个晚上的大床房（单早）。 谢谢 祝好 罗一丹 20251110 | H18: 已更改
G19: 您好： 我是郑光洁（个人代表信息 注册号：3922）， 我预定了12.27-12.2的“江门富力万达嘉华酒店（VIP预留）“，订单编号21198109，订单信息如附件。 现因行程变更，希望将预订信息更改为： 12.28（入住）-12.30（退房），共2晚 房型及其它信息不变。 请协助变更。谢谢！ 祝好， 郑光洁 | H19: 已更改
G20: 会务组老师好，我是西北农林科技大学的贾汉忠，电话15399421323，会议注册号3895。之前预定了 名冠金凯悦酒店（VIP预留酒店）且付费，原计划入住时间11月28日，现需要变更为29日入住，请给予处理。 发自我的手机 | H20: 不听电话
G21: 您好，我预定了江门丽宫国际酒店（VIP预留） A座高级大床房（单早） （整间） （2*6晚） 我在网站上申请了退款，但担心退款成功后没有房间了，所以发邮件问一下是否能帮忙直接修改，保留我的订单，将入住日期修改成11月28日，退房日期为12月2日，房间数量修改为1间。谢谢！ 史亚利 中国科学院生态环境研究中心 环境化学与生态毒理学国家重点实验室 离子色谱和新型污染物分析研究组 e-mail:shiyali@rcees.ac.cn | H21: 已处理
G22: 会务组老师好，我是西北农林科技大学的贾汉忠，电话15399421323，会议注册号3895。之前预定了 名冠金凯悦酒店（VIP预留酒店）且付费，原计划入住时间11月28日，现需要变更为29日入住，请给予处理。 发自我的手机 | H22: 不听电话
G23: 尊敬的环化大会工作人员： 您好！ 我是冯翠杰，我已预定了江门丽宫国际酒店，11月28日至12月2日的酒店（4个晚上），订单信息如下截图。但是由于行程有变，麻烦您将酒店入住时间修改为11月28日至12月2日，共2个晚上。 请问如何操作，我已支付过费用，如何退掉多支付的部分？ 谢谢，盼复。 预祝会议取得圆满成功。 | H23: 已修改
G24: 您好， 我之前在网上预订了铂顿国际公寓江门蓬江行政服务中心店11.28入住 12.1退房 （详见截图） 现行程有变，11.28入住，11.30日退房。还请您帮助修改。 非常感谢！ 宋文静 | H24: 不听电话
G25: 会务老师， 您好！山东大学薛丽坤老师（个人代表，注册号2653）参加第十三届环境化学大会，已经预定了酒店房间并支付费用（名冠金凯悦酒店（VIP预留），广东省江门蓬江区发展大道188号），原定11月29日入住，12月1日退房，共2个晚上，费用876元已支付，详细信息见附件。由于工作安排有变动，需要改为11月29日入住（入住时间不变），11月30日退房（提前一天退房），特申请变更住宿日期，并烦请原路退回一晚住宿费用。给您带来不便之处敬请谅解！如有问题请联系我，电话18266208096，谢谢！ 祝好！ 连曦 山东大学环境研究院 0532-58631962，18266208096 lianxi@sdu.edu.cn | H25: 已修改
B26: 刘倩 | C26: 18810276437 | F26: 将退房时间延长至12月1日，订单编号（21090324） | G26: =_xlfn.DISPIMG("ID_1D1D1CFD776343ACAA1454DE8116F2F3",1) -> =DISPIMG("ID_1D1D1CFD776343ACAA1454DE8116F2F3",1) | H26: 已处理
B27: 杨欣 | D27: 江门丽宫国际酒店 | F27: 将入住时间从“11.28-12.1日”改为“11.28-11.30日” | G27: =_xlfn.DISPIMG("ID_8318A49599604442A361CFF80441F9A9",1) -> =DISPIMG("ID_8318A49599604442A361CFF80441F9A9",1)
B28: 侯杰 | D28: 名冠金凯悦酒店 | F28: 林道辉教授想把原订酒店的日期调整到11.28入住-12.1离店。 侯杰想调整到11.28入住-11.30离店. | G28: =_xlfn.DISPIMG("ID_D27DDDC814D54421A08C71255BB15535",1) -> =DISPIMG("ID_D27DDDC814D54421A08C71255BB15535",1)
G29: 申请人信息 姓名:汪金辉; 手机号:15365346625; 注册号:6343。 发票抬头:上海交通大学 税号: 1210000042500615X0 备注：汪金辉住宿，11.28-12.02 | H29: 要开发票
G30: 注册人姓名：丁玎， 单位：北京市科学技术研究院城市安全与环境科学研究所 注册人手机号：18810810622 注册号：1999 | H30: 要开发票

Sheet WpsReserved_CellImgList
